Workbook

Sheet benchmark_results
A1: round | B1: algo | C1: n_tracks | D1: target_s | E1: runtime_s | F1: gap_s | G1: timed_out
A2: 0 | B2: design_playlist_v1 | C2: 10 | D2: 300 | G2: TRUE
A3: 0 | B3: design_playlist_v2 | C3: 10 | D3: 300 | E3: 0.0001076 | F3: 0 | G3: FALSE
A4: 0 | B4: design_playlist_v3 | C4: 10 | D4: 300 | E4: 4.8999995e-05 | F4: 0 | G4: FALSE
A5: 0 | B5: design_playlist_v4 | C5: 10 | D5: 300 | E5: 4.8400005e-05 | F5: 0 | G5: FALSE
A6: 0 | B6: design_playlist_v1 | C6: 30 | D6: 300 | G6: TRUE
A7: 0 | B7: design_playlist_v2 | C7: 30 | D7: 300 | E7: 0.001869 | F7: 0 | G7: FALSE
A8: 0 | B8: design_playlist_v3 | C8: 30 | D8: 300 | E8: 0.0002138 | F8: 0 | G8: FALSE
A9: 0 | B9: design_playlist_v4 | C9: 30 | D9: 300 | E9: 0.00014020001 | F9: 0 | G9: FALSE
A10: 0 | B10: design_playlist_v1 | C10: 50 | D10: 300 | G10: TRUE
A11: 0 | B11: design_playlist_v2 | C11: 50 | D11: 300 | E11: 0.0129738 | F11: 0 | G11: FALSE
A12: 0 | B12: design_playlist_v3 | C12: 50 | D12: 300 | E12: 0.0004772 | F12: 0 | G12: FALSE
A13: 0 | B13: design_playlist_v4 | C13: 50 | D13: 300 | E13: 0.000556 | F13: 0 | G13: FALSE
A14: 0 | B14: design_playlist_v1 | C14: 100 | D14: 300 | E14: 9.6100004e-05 | F14: 0 | G14: FALSE
A15: 0 | B15: design_playlist_v2 | C15: 100 | D15: 300 | E15: 0.2571056 | F15: 0 | G15: FALSE
A16: 0 | B16: design_playlist_v3 | C16: 100 | D16: 300 | E16: 0.0024922 | F16: 0 | G16: FALSE
A17: 0 | B17: design_playlist_v4 | C17: 100 | D17: 300 | E17: 0.0023407 | F17: 0 | G17: FALSE
A18: 0 | B18: design_playlist_v1 | C18: 200 | D18: 300 | E18: 0.0004853 | F18: 0 | G18: FALSE
A19: 0 | B19: design_playlist_v2 | C19: 200 | D19: 300 | G19: TRUE
A20: 0 | B20: design_playlist_v3 | C20: 200 | D20: 300 | E20: 0.0096613 | F20: 0 | G20: FALSE
A21: 0 | B21: design_playlist_v4 | C21: 200 | D21: 300 | E21: 0.0066784 | F21: 0 | G21: FALSE
A22: 0 | B22: design_playlist_v1 | C22: 400 | D22: 300 | E22: 0.0002594 | F22: 0 | G22: FALSE
A23: 0 | B23: design_playlist_v2 | C23: 400 | D23: 300 | G23: TRUE
A24: 0 | B24: design_playlist_v3 | C24: 400 | D24: 300 | E24: 0.0171225 | F24: 0 | G24: FALSE
A25: 0 | B25: design_playlist_v4 | C25: 400 | D25: 300 | E25: 0.0121063 | F25: 0 | G25: FALSE
A26: 0 | B26: design_playlist_v1 | C26: 10 | D26: 600 | G26: TRUE
A27: 0 | B27: design_playlist_v2 | C27: 10 | D27: 600 | E27: 0.00019179999 | F27: 1 | G27: FALSE
A28: 0 | B28: design_playlist_v3 | C28: 10 | D28: 600 | E28: 0.00010379999 | F28: 1 | G28: FALSE
A29: 0 | B29: design_playlist_v4 | C29: 10 | D29: 600 | E29: 9.8699995e-05 | F29: 1 | G29: FALSE
A30: 0 | B30: design_playlist_v1 | C30: 30 | D30: 600 | G30: TRUE
A31: 0 | B31: design_playlist_v2 | C31: 30 | D31: 600 | E31: 0.2012925 | F31: 0 | G31: FALSE
A32: 0 | B32: design_playlist_v3 | C32: 30 | D32: 600 | E32: 0.0032198 | F32: 0 | G32: FALSE
A33: 0 | B33: design_playlist_v4 | C33: 30 | D33: 600 | E33: 0.0011334 | F33: 0 | G33: FALSE
A34: 0 | B34: design_playlist_v1 | C34: 50 | D34: 600 | E34: 0.0013281 | F34: 0 | G34: FALSE
A35: 0 | B35: design_playlist_v2 | C35: 50 | D35: 600 | E35: 2.0185901 | F35: 0 | G35: FALSE
A36: 0 | B36: design_playlist_v3 | C36: 50 | D36: 600 | E36: 0.0047539 | F36: 0 | G36: FALSE
A37: 0 | B37: design_playlist_v4 | C37: 50 | D37: 600 | E37: 0.002092 | F37: 0 | G37: FALSE
A38: 0 | B38: design_playlist_v1 | C38: 100 | D38: 600 | E38: 0.0003647 | F38: 0 | G38: FALSE
A39: 0 | B39: design_playlist_v2 | C39: 100 | D39: 600 | G39: TRUE
A40: 0 | B40: design_playlist_v3 | C40: 100 | D40: 600 | E40: 0.0112992 | F40: 0 | G40: FALSE
...

Sheet Summary
A1: Benchmark Analysis — design_playlist v1 to v4
A2: Source: benchmark_results table (600 runs = 5 rounds x 4 algorithms x 6 playlist sizes x 5 duration targets). Runtime is blank where a run timed out.
A4: Metric | B4: design_playlist_v1 | C4: design_playlist_v2 | D4: design_playlist_v3 | E4: design_playlist_v4
A5: Coverage & reliability
A6: Runs attempted | B6: =COUNTIFS(benchmark_results[algo],B$4) -> 150 | C6: =COUNTIFS(benchmark_results[algo],C$4) -> 150 | D6: =COUNTIFS(benchmark_results[algo],D$4) -> 150 | E6: =COUNTIFS(benchmark_results[algo],E$4) -> 150
A7: Runs completed | B7: =COUNTIFS(benchmark_results[algo],B$4,benchmark_results[timed_out],FALSE) -> 111 | C7: =COUNTIFS(benchmark_results[algo],C$4,benchmark_results[timed_out],FALSE) -> 55 | D7: =COUNTIFS(benchmark_results[algo],D$4,benchmark_results[timed_out],FALSE) -> 150 | E7: =COUNTIFS(benchmark_results[algo],E$4,benchmark_results[timed_out],FALSE) -> 150
A8: Runs timed out | B8: =COUNTIFS(benchmark_results[algo],B$4,benchmark_results[timed_out],TRUE) -> 39 | C8: =COUNTIFS(benchmark_results[algo],C$4,benchmark_results[timed_out],TRUE) -> 95 | D8: =COUNTIFS(benchmark_results[algo],D$4,benchmark_results[timed_out],TRUE) -> 0 | E8: =COUNTIFS(benchmark_results[algo],E$4,benchmark_results[timed_out],TRUE) -> 0
A9: Timeout rate | B9: =B8/B6 -> 0.26 | C9: =C8/C6 -> 0.63333333 | D9: =D8/D6 -> 0 | E9: =E8/E6 -> 0
A10: Sizes with >=1 timeout (of 6) | B10: {=SUMPRODUCT(--(COUNTIFS(benchmark_results[algo],B$4,benchmark_results[timed_out],TRUE,benchmark_results[n_tracks],'By Size'!$A$5:$A$10)>0))} -> 5 | C10: {=SUMPRODUCT(--(COUNTIFS(benchmark_results[algo],C$4,benchmark_results[timed_out],TRUE,benchmark_results[n_tracks],'By Size'!$A$5:$A$10)>0))} -> 5 | D10: {=SUMPRODUCT(--(COUNTIFS(benchmark_results[algo],D$4,benchmark_results[timed_out],TRUE,benchmark_results[n_tracks],'By Size'!$A$5:$A$10)>0))} -> 0 | E10: {=SUMPRODUCT(--(COUNTIFS(benchmark_results[algo],E$4,benchmark_results[timed_out],TRUE,benchmark_results[n_tracks],'By Size'!$A$5:$A$10)>0))} -> 0
A11: Targets with >=1 timeout (of 5) | B11: {=SUMPRODUCT(--(COUNTIFS(benchmark_results[algo],B$4,benchmark_results[timed_out],TRUE,benchmark_results[target_s],'By Target'!$A$5:$A$9)>0))} -> 4 | C11: {=SUMPRODUCT(--(COUNTIFS(benchmark_results[algo],C$4,benchmark_results[timed_out],TRUE,benchmark_results[target_s],'By Target'!$A$5:$A$9)>0))} -> 5 | D11: {=SUMPRODUCT(--(COUNTIFS(benchmark_results[algo],D$4,benchmark_results[timed_out],TRUE,benchmark_results[target_s],'By Target'!$A$5:$A$9)>0))} -> 0 | E11: {=SUMPRODUCT(--(COUNTIFS(benchmark_results[algo],E$4,benchmark_results[timed_out],TRUE,benchmark_results[target_s],'By Target'!$A$5:$A$9)>0))} -> 0
A13: Runtime on completed runs (seconds)
A14: Mean | B14: =AVERAGEIFS(benchmark_results[runtime_s],benchmark_results[algo],B$4) -> 0.0009449973 | C14: =AVERAGEIFS(benchmark_results[runtime_s],benchmark_results[algo],C$4) -> 0.3359013 | D14: =AVERAGEIFS(benchmark_results[runtime_s],benchmark_results[algo],D$4) -> 0.25626694 | E14: =AVERAGEIFS(benchmark_results[runtime_s],benchmark_results[algo],E$4) -> 0.087146811
A15: Median | B15: {=MEDIAN(_xlfn._xlws.FILTER(benchmark_results[runtime_s],(benchmark_results[algo]=B$4)*(benchmark_results[timed_out]=FALSE)))} -> 0.000443 | C15: {=MEDIAN(_xlfn._xlws.FILTER(benchmark_results[runtime_s],(benchmark_results[algo]=C$4)*(benchmark_results[timed_out]=FALSE)))} -> 0.0018799 | D15: {=MEDIAN(_xlfn._xlws.FILTER(benchmark_results[runtime_s],(benchmark_results[algo]=D$4)*(benchmark_results[timed_out]=FALSE)))} -> 0.02702425 | E15: {=MEDIAN(_xlfn._xlws.FILTER(benchmark_results[runtime_s],(benchmark_results[algo]=E$4)*(benchmark_results[timed_out]=FALSE)))} -> 0.01081415
A16: Geometric mean | B16: {=GEOMEAN(_xlfn._xlws.FILTER(benchmark_results[runtime_s],(benchmark_results[algo]=B$4)*(benchmark_results[timed_out]=FALSE)))} -> 0.00038480206 | C16: {=GEOMEAN(_xlfn._xlws.FILTER(benchmark_results[runtime_s],(benchmark_results[algo]=C$4)*(benchmark_results[timed_out]=FALSE)))} -> 0.0066228819 | D16: {=GEOMEAN(_xlfn._xlws.FILTER(benchmark_results[runtime_s],(benchmark_results[algo]=D$4)*(benchmark_results[timed_out]=FALSE)))} -> 0.016720032 | E16: {=GEOMEAN(_xlfn._xlws.FILTER(benchmark_results[runtime_s],(benchmark_results[algo]=E$4)*(benchmark_results[timed_out]=FALSE)))} -> 0.0076975233
A17: 95th percentile | B17: {=_xlfn.PERCENTILE.INC(_xlfn._xlws.FILTER(benchmark_results[runtime_s],(benchmark_results[algo]=B$4)*(benchmark_results[timed_out]=FALSE)),0.95)} -> 0.00321775 | C17: {=_xlfn.PERCENTILE.INC(_xlfn._xlws.FILTER(benchmark_results[runtime_s],(benchmark_results[algo]=C$4)*(benchmark_results[timed_out]=FALSE)),0.95)} -> 1.2883005 | D17: {=_xlfn.PERCENTILE.INC(_xlfn._xlws.FILTER(benchmark_results[runtime_s],(benchmark_results[algo]=D$4)*(benchmark_results[timed_out]=FALSE)),0.95)} -> 1.1870118 | E17: {=_xlfn.PERCENTILE.INC(_xlfn._xlws.FILTER(benchmark_results[runtime_s],(benchmark_results[algo]=E$4)*(benchmark_results[timed_out]=FALSE)),0.95)} -> 0.45106054
A18: Minimum | B18: =_xlfn.MINIFS(benchmark_results[runtime_s],benchmark_results[algo],B$4) -> 1.7700004e-05 | C18: =_xlfn.MINIFS(benchmark_results[runtime_s],benchmark_results[algo],C$4) -> 7.3500007e-05 | D18: =_xlfn.MINIFS(benchmark_results[runtime_s],benchmark_results[algo],D$4) -> 4.1499996e-05 | E18: =_xlfn.MINIFS(benchmark_results[runtime_s],benchmark_results[algo],E$4) -> 3.63e-05
A19: Maximum | B19: =_xlfn.MAXIFS(benchmark_results[runtime_s],benchmark_results[algo],B$4) -> 0.0113342 | C19: =_xlfn.MAXIFS(benchmark_results[runtime_s],benchmark_results[algo],C$4) -> 7.0573739 | D19: =_xlfn.MAXIFS(benchmark_results[runtime_s],benchmark_results[algo],D$4) -> 4.1035292 | E19: =_xlfn.MAXIFS(benchmark_results[runtime_s],benchmark_results[algo],E$4) -> 1.490365
A20: Total compute time | B20: =SUMIFS(benchmark_results[runtime_s],benchmark_results[algo],B$4) -> 0.1048947 | C20: =SUMIFS(benchmark_results[runtime_s],benchmark_results[algo],C$4) -> 18.474571 | D20: =SUMIFS(benchmark_results[runtime_s],benchmark_results[algo],D$4) -> 38.440041 | E20: =SUMIFS(benchmark_results[runtime_s],benchmark_results[algo],E$4) -> 13.072022
A22: Solution quality (gap_s = seconds away from target)
A23: Completed runs hitting target exactly (gap = 0) | B23: =COUNTIFS(benchmark_results[algo],B$4,benchmark_results[gap_s],0) -> 101 | C23: =COUNTIFS(benchmark_results[algo],C$4,benchmark_results[gap_s],0) -> 35 | D23: =COUNTIFS(benchmark_results[algo],D$4,benchmark_results[gap_s],0) -> 125 | E23: =COUNTIFS(benchmark_results[algo],E$4,benchmark_results[gap_s],0) -> 129
A24: Share of completed runs with gap = 0 | B24: =B23/B7 -> 0.90990991 | C24: =C23/C7 -> 0.63636364 | D24: =D23/D7 -> 0.83333333 | E24: =E23/E7 -> 0.86
A25: Mean gap, all completed runs | B25: =AVERAGEIFS(benchmark_results[gap_s],benchmark_results[algo],B$4,benchmark_results[timed_out],FALSE) -> 247.66667 | C25: =AVERAGEIFS(benchmark_results[gap_s],benchmark_results[algo],C$4,benchmark_results[timed_out],FALSE) -> 500.52727 | D25: =AVERAGEIFS(benchmark_results[gap_s],benchmark_results[algo],D$4,benchmark_results[timed_out],FALSE) -> 186.88 | E25: =AVERAGEIFS(benchmark_results[gap_s],benchmark_results[algo],E$4,benchmark_results[timed_out],FALSE) -> 183.54667
A26: Max gap | B26: =_xlfn.MAXIFS(benchmark_results[gap_s],benchmark_results[algo],B$4) -> 5071 | C26: =_xlfn.MAXIFS(benchmark_results[gap_s],benchmark_results[algo],C$4) -> 5071 | D26: =_xlfn.MAXIFS(benchmark_results[gap_s],benchmark_results[algo],D$4) -> 5213 | E26: =_xlfn.MAXIFS(benchmark_results[gap_s],benchmark_results[algo],E$4) -> 5071
A27: Feasible instances only (n_tracks > 10)
A28: Completed runs with gap > 0 | B28: =COUNTIFS(benchmark_results[algo],B$4,benchmark_results[gap_s],">0",benchmark_results[n_tracks],">10") -> 0 | C28: =COUNTIFS(benchmark_results[algo],C$4,benchmark_results[gap_s],">0",benchmark_results[n_tracks],">10") -> 1 | D28: =COUNTIFS(benchmark_results[algo],D$4,benchmark_results[gap_s],">0",benchmark_results[n_tracks],">10") -> 5 | E28: =COUNTIFS(benchmark_results[algo],E$4,benchmark_results[gap_s],">0",benchmark_results[n_tracks],">10") -> 1
A29: Mean gap | B29: =AVERAGEIFS(benchmark_results[gap_s],benchmark_results[algo],B$4,benchmark_results[timed_out],FALSE,benchmark_results[n_tracks],">10") -> 0 | C29: =AVERAGEIFS(benchmark_results[gap_s],benchmark_results[algo],C$4,benchmark_results[timed_out],FALSE,benchmark_results[n_tracks],">10") -> 0.033333333 | D29: =AVERAGEIFS(benchmark_results[gap_s],benchmark_results[algo],D$4,benchmark_results[timed_out],FALSE,benchmark_results[n_tracks],">10") -> 0.232 | E29: =AVERAGEIFS(benchmark_results[gap_s],benchmark_results[algo],E$4,benchmark_results[timed_out],FALSE,benchmark_results[n_tracks],">10") -> 0.008
A30: Max gap | B30: =_xlfn.MAXIFS(benchmark_results[gap_s],benchmark_results[algo],B$4,benchmark_results[n_tracks],">10") -> 0 | C30: =_xlfn.MAXIFS(benchmark_results[gap_s],benchmark_results[algo],C$4,benchmark_results[n_tracks],">10") -> 1 | D30: =_xlfn.MAXIFS(benchmark_results[gap_s],benchmark_results[algo],D$4,benchmark_results[n_tracks],">10") -> 24 | E30: =_xlfn.MAXIFS(benchmark_results[gap_s],benchmark_results[algo],E$4,benchmark_results[n_tracks],">10") -> 1
A32: Findings
A33: 1. Only v3 and v4 are viable. Both completed all 150 instances. v1 timed out on 39 of 150 runs (26%), v2 on 95 of 150 (63%).
A34: 2. v4 is the best algorithm overall. On the 150 matched instances it beats v3 in 144, is at least 2x faster in 96, median speed-up 2.4x (geometric mean 2.2x), worst case still 0.86x. It never leaves a larger gap than v3 (gaps identical in 142 instances, v3 worse in 8, by up to 266 s).
A35: 3. v4 is also the most stable. Coefficient of variation of median runtime across the 5 rounds: v4 3.5%, v2 10.6%, v3 14.6%, v1 23.2%. Worst single run: v4 1.49 s vs v3 4.10 s vs v2 7.06 s.
A36: 4. v2 does not scale. Timeouts rise monotonically with playlist size (0, 10, 15, 20, 25, 25 out of 25 runs at n = 10, 30, 50, 100, 200, 400) - it never finished a single run at n = 200 or 400. Where it does finish, its median runtime at n = 100 (0.358 s) is already 25x v4's.
A37: 5. v1's apparent speed is an artefact, not a win. Its median runtime is 0.0004 s, but its timeouts concentrate on the EASIEST instances (15 of 25 at n = 10; 20 of 30 at target = 300 s) and disappear at large n. That is the signature of a solver that exits immediately and fails rather than searching, so its 110 'fastest per instance' wins should be discounted.
A38: 6. Scaling is super-linear in playlist size for both viable algorithms: v3 grows as n^1.62 (R2 = 0.94), v4 as n^1.44 (R2 = 0.97) - i.e. 3.1x and 2.7x runtime per doubling of catalogue size. Runtime also grows with the duration target: v4's median goes 0.001 s (300 s target) to 0.117 s (7200 s target).
A39: 7. Solution quality is essentially a tie and near-perfect. v4 hits the target exactly in 129 of 150 runs (86%), v3 in 125 of 150 (83%). Restricted to feasible instances (n_tracks > 10), v4 misses in 1 run by 1 s and v3 in 5 runs by up to 24 s.
A40: 8. The huge gaps in the data are instance infeasibility, not algorithm error: every algorithm misses by ~1,100-5,200 s at n_tracks = 10 with 3600 s / 7200 s targets, because 10 tracks cannot fill 1-2 hours. Exclude that row before judging quality.
A41: 9. Total suite cost: v4 13.1 s vs v3 38.4 s of compute for identical coverage - v4 is ~2.9x cheaper to run end to end.
A43: Recommendation
A44: Ship v4 as the default; keep v3 as a fallback since it is the only other algorithm with full coverage and matches v4 on quality. Retire v2 (unusable above n = 100). Treat v1 as a defect rather than a slow algorithm: investigate why it times out on the smallest, shortest instances while succeeding on larger ones.

Sheet By Size
A1: Runtime & reliability by playlist size (n_tracks)
A2: Aggregated across 5 rounds x 5 duration targets = 25 runs per algorithm per size. Runtime statistics cover completed runs only.
B3: Median runtime (s), completed runs | G3: Max runtime (s), completed runs | L3: Timeouts (of 25 runs) | Q3: Mean gap (s), completed runs | V3: Chart source — median runtime (s); #N/A = never completed | AB3: Chart source — timeouts (of 25 runs)
A4: n_tracks | B4: design_playlist_v1 | C4: design_playlist_v2 | D4: design_playlist_v3 | E4: design_playlist_v4 | F4: n_tracks | G4: design_playlist_v1 | H4: design_playlist_v2 | I4: design_playlist_v3 | J4: design_playlist_v4 | K4: n_tracks | L4: design_playlist_v1 | M4: design_playlist_v2 | N4: design_playlist_v3 | O4: design_playlist_v4 | P4: n_tracks | Q4: design_playlist_v1 | R4: design_playlist_v2 | S4: design_playlist_v3 | T4: design_playlist_v4 | V4: n_tracks | W4: v1 | X4: v2 | Y4: v3 | Z4: v4 | AB4: n_tracks | AC4: v1 | AD4: v2 | AE4: v3 | AF4: v4
A5: 10 | B5: {=IFERROR(MEDIAN(_xlfn._xlws.FILTER(benchmark_results[runtime_s],(benchmark_results[algo]=B$4)*(benchmark_results[n_tracks]=$A5)*(benchmark_results[timed_out]=FALSE))),"n/a")} -> 2.1100001e-05 | C5: {=IFERROR(MEDIAN(_xlfn._xlws.FILTER(benchmark_results[runtime_s],(benchmark_results[algo]=C$4)*(benchmark_results[n_tracks]=$A5)*(benchmark_results[timed_out]=FALSE))),"n/a")} -> 0.0003768 | D5: {=IFERROR(MEDIAN(_xlfn._xlws.FILTER(benchmark_results[runtime_s],(benchmark_results[algo]=D$4)*(benchmark_results[n_tracks]=$A5)*(benchmark_results[timed_out]=FALSE))),"n/a")} -> 0.0003517 | E5: {=IFERROR(MEDIAN(_xlfn._xlws.FILTER(benchmark_results[runtime_s],(benchmark_results[algo]=E$4)*(benchmark_results[n_tracks]=$A5)*(benchmark_results[timed_out]=FALSE))),"n/a")} -> 0.00026 | F5: =$A5 -> 10 | G5: =IF(COUNTIFS(benchmark_results[algo],G$4,benchmark_results[n_tracks],$A5,benchmark_results[timed_out],FALSE)=0,"n/a",_xlfn.MAXIFS(benchmark_results[runtime_s],benchmark_results[algo],G$4,benchmark_results[n_tracks],$A5)) -> 3.9399994e-05 | H5: =IF(COUNTIFS(benchmark_results[algo],H$4,benchmark_results[n_tracks],$A5,benchmark_results[timed_out],FALSE)=0,"n/a",_xlfn.MAXIFS(benchmark_results[runtime_s],benchmark_results[algo],H$4,benchmark_results[n_tracks],$A5)) -> 0.00073489999 | I5: =IF(COUNTIFS(benchmark_results[algo],I$4,benchmark_results[n_tracks],$A5,benchmark_results[timed_out],FALSE)=0,"n/a",_xlfn.MAXIFS(benchmark_results[runtime_s],benchmark_results[algo],I$4,benchmark_results[n_tracks],$A5)) -> 0.0008214 | J5: =IF(COUNTIFS(benchmark_results[algo],J$4,benchmark_results[n_tracks],$A5,benchmark_results[timed_out],FALSE)=0,"n/a",_xlfn.MAXIFS(benchmark_results[runtime_s],benchmark_results[algo],J$4,benchmark_results[n_tracks],$A5)) -> 0.0006573 | K5: =$A5 -> 10 | L5: =COUNTIFS(benchmark_results[algo],L$4,benchmark_results[n_tracks],$A5,benchmark_results[timed_out],TRUE) -> 15 | M5: =COUNTIFS(benchmark_results[algo],M$4,benchmark_results[n_tracks],$A5,benchmark_results[timed_out],TRUE) -> 0 | N5: =COUNTIFS(benchmark_results[algo],N$4,benchmark_results[n_tracks],$A5,benchmark_results[timed_out],TRUE) -> 0 | O5: =COUNTIFS(benchmark_results[algo],O$4,benchmark_results[n_tracks],$A5,benchmark_results[timed_out],TRUE) -> 0 | P5: =$A5 -> 10 | Q5: =IFERROR(AVERAGEIFS(benchmark_results[gap_s],benchmark_results[algo],Q$4,benchmark_results[n_tracks],$A5,benchmark_results[timed_out],FALSE),"n/a") -> 2749.1 | R5: =IFERROR(AVERAGEIFS(benchmark_results[gap_s],benchmark_results[algo],R$4,benchmark_results[n_tracks],$A5,benchmark_results[timed_out],FALSE),"n/a") -> 1101.12 | S5: =IFERROR(AVERAGEIFS(benchmark_results[gap_s],benchmark_results[algo],S$4,benchmark_results[n_tracks],$A5,benchmark_results[timed_out],FALSE),"n/a") -> 1120.12 | T5: =IFERROR(AVERAGEIFS(benchmark_results[gap_s],benchmark_results[algo],T$4,benchmark_results[n_tracks],$A5,benchmark_results[timed_out],FALSE),"n/a") -> 1101.24 | V5: =TEXT($A5,"0") -> 10 | W5: {=IFERROR(MEDIAN(_xlfn._xlws.FILTER(benchmark_results[runtime_s],(benchmark_results[algo]="design_playlist_"&W$4)*(benchmark_results[n_tracks]=$A5)*(benchmark_results[timed_out]=FALSE))),NA())} -> 2.1100001e-05 | X5: {=IFERROR(MEDIAN(_xlfn._xlws.FILTER(benchmark_results[runtime_s],(benchmark_results[algo]="design_playlist_"&X$4)*(benchmark_results[n_tracks]=$A5)*(benchmark_results[timed_out]=FALSE))),NA())} -> 0.0003768 | Y5: {=IFERROR(MEDIAN(_xlfn._xlws.FILTER(benchmark_results[runtime_s],(benchmark_results[algo]="design_playlist_"&Y$4)*(benchmark_results[n_tracks]=$A5)*(benchmark_results[timed_out]=FALSE))),NA())} -> 0.0003517 | Z5: {=IFERROR(MEDIAN(_xlfn._xlws.FILTER(benchmark_results[runtime_s],(benchmark_results[algo]="design_playlist_"&Z$4)*(benchmark_results[n_tracks]=$A5)*(benchmark_results[timed_out]=FALSE))),NA())} -> 0.00026 | AB5: =TEXT($A5,"0") -> 10 | AC5: =COUNTIFS(benchmark_results[algo],"design_playlist_"&AC$4,benchmark_results[n_tracks],$A5,benchmark_results[timed_out],TRUE) -> 15 | AD5: =COUNTIFS(benchmark_results[algo],"design_playlist_"&AD$4,benchmark_results[n_tracks],$A5,benchmark_results[timed_out],TRUE) -> 0 | AE5: =COUNTIFS(benchmark_results[algo],"design_playlist_"&AE$4,benchmark_results[n_tracks],$A5,benchmark_results[timed_out],TRUE) -> 0 | AF5: =COUNTIFS(benchmark_results[algo],"design_playlist_"&AF$4,benchmark_results[n_tracks],$A5,benchmark_results[timed_out],TRUE) -> 0
A6: 30 | B6: {=IFERROR(MEDIAN(_xlfn._xlws.FILTER(benchmark_results[runtime_s],(benchmark_results[algo]=B$4)*(benchmark_results[n_tracks]=$A6)*(benchmark_results[timed_out]=FALSE))),"n/a")} -> 0.0002581 | C6: {=IFERROR(MEDIAN(_xlfn._xlws.FILTER(benchmark_results[runtime_s],(benchmark_results[algo]=C$4)*(benchmark_results[n_tracks]=$A6)*(benchmark_results[timed_out]=FALSE))),"n/a")} -> 0.0280758 | D6: {=IFERROR(MEDIAN(_xlfn._xlws.FILTER(benchmark_results[runtime_s],(benchmark_results[algo]=D$4)*(benchmark_results[n_tracks]=$A6)*(benchmark_results[timed_out]=FALSE))),"n/a")} -> 0.00908 | E6: {=IFERROR(MEDIAN(_xlfn._xlws.FILTER(benchmark_results[runtime_s],(benchmark_results[algo]=E$4)*(benchmark_results[n_tracks]=$A6)*(benchmark_results[timed_out]=FALSE))),"n/a")} -> 0.0031425 | F6: =$A6 -> 30 | G6: =IF(COUNTIFS(benchmark_results[algo],G$4,benchmark_results[n_tracks],$A6,benchmark_results[timed_out],FALSE)=0,"n/a",_xlfn.MAXIFS(benchmark_results[runtime_s],benchmark_results[algo],G$4,benchmark_results[n_tracks],$A6)) -> 0.0014995 | H6: =IF(COUNTIFS(benchmark_results[algo],H$4,benchmark_results[n_tracks],$A6,benchmark_results[timed_out],FALSE)=0,"n/a",_xlfn.MAXIFS(benchmark_results[runtime_s],benchmark_results[algo],H$4,benchmark_results[n_tracks],$A6)) -> 7.0573739 | I6: =IF(COUNTIFS(benchmark_results[algo],I$4,benchmark_results[n_tracks],$A6,benchmark_results[timed_out],FALSE)=0,"n/a",_xlfn.MAXIFS(benchmark_results[runtime_s],benchmark_results[algo],I$4,benchmark_results[n_tracks],$A6)) -> 0.0600418 | J6: =IF(COUNTIFS(benchmark_results[algo],J$4,benchmark_results[n_tracks],$A6,benchmark_results[timed_out],FALSE)=0,"n/a",_xlfn.MAXIFS(benchmark_results[runtime_s],benchmark_results[algo],J$4,benchmark_results[n_tracks],$A6)) -> 0.0192623 | K6: =$A6 -> 30 | L6: =COUNTIFS(benchmark_results[algo],L$4,benchmark_results[n_tracks],$A6,benchmark_results[timed_out],TRUE) -> 12 | M6: =COUNTIFS(benchmark_results[algo],M$4,benchmark_results[n_tracks],$A6,benchmark_results[timed_out],TRUE) -> 10 | N6: =COUNTIFS(benchmark_results[algo],N$4,benchmark_results[n_tracks],$A6,benchmark_results[timed_out],TRUE) -> 0 | O6: =COUNTIFS(benchmark_results[algo],O$4,benchmark_results[n_tracks],$A6,benchmark_results[timed_out],TRUE) -> 0 | P6: =$A6 -> 30 | Q6: =IFERROR(AVERAGEIFS(benchmark_results[gap_s],benchmark_results[algo],Q$4,benchmark_results[n_tracks],$A6,benchmark_results[timed_out],FALSE),"n/a") -> 0 | R6: =IFERROR(AVERAGEIFS(benchmark_results[gap_s],benchmark_results[algo],R$4,benchmark_results[n_tracks],$A6,benchmark_results[timed_out],FALSE),"n/a") -> 0.066666667 | S6: =IFERROR(AVERAGEIFS(benchmark_results[gap_s],benchmark_results[algo],S$4,benchmark_results[n_tracks],$A6,benchmark_results[timed_out],FALSE),"n/a") -> 1.16 | T6: =IFERROR(AVERAGEIFS(benchmark_results[gap_s],benchmark_results[algo],T$4,benchmark_results[n_tracks],$A6,benchmark_results[timed_out],FALSE),"n/a") -> 0.04 | V6: =TEXT($A6,"0") -> 30 | W6: {=IFERROR(MEDIAN(_xlfn._xlws.FILTER(benchmark_results[runtime_s],(benchmark_results[algo]="design_playlist_"&W$4)*(benchmark_results[n_tracks]=$A6)*(benchmark_results[timed_out]=FALSE))),NA())} -> 0.0002581 | X6: {=IFERROR(MEDIAN(_xlfn._xlws.FILTER(benchmark_results[runtime_s],(benchmark_results[algo]="design_playlist_"&X$4)*(benchmark_results[n_tracks]=$A6)*(benchmark_results[timed_out]=FALSE))),NA())} -> 0.0280758 | Y6: {=IFERROR(MEDIAN(_xlfn._xlws.FILTER(benchmark_results[runtime_s],(benchmark_results[algo]="design_playlist_"&Y$4)*(benchmark_results[n_tracks]=$A6)*(benchmark_results[timed_out]=FALSE))),NA())} -> 0.00908 | Z6: {=IFERROR(MEDIAN(_xlfn._xlws.FILTER(benchmark_results[runtime_s],(benchmark_results[algo]="design_playlist_"&Z$4)*(benchmark_results[n_tracks]=$A6)*(benchmark_results[timed_out]=FALSE))),NA())} -> 0.0031425 | AB6: =TEXT($A6,"0") -> 30 | AC6: =COUNTIFS(benchmark_results[algo],"design_playlist_"&AC$4,benchmark_results[n_tracks],$A6,benchmark_results[timed_out],TRUE) -> 12 | AD6: =COUNTIFS(benchmark_results[algo],"design_playlist_"&AD$4,benchmark_results[n_tracks],$A6,benchmark_results[timed_out],TRUE) -> 10 | AE6: =COUNTIFS(benchmark_results[algo],"design_playlist_"&AE$4,benchmark_results[n_tracks],$A6,benchmark_results[timed_out],TRUE) -> 0 | AF6: =COUNTIFS(benchmark_results[algo],"design_playlist_"&AF$4,benchmark_results[n_tracks],$A6,benchmark_results[timed_out],TRUE) -> 0
A7: 50 | B7: {=IFERROR(MEDIAN(_xlfn._xlws.FILTER(benchmark_results[runtime_s],(benchmark_results[algo]=B$4)*(benchmark_results[n_tracks]=$A7)*(benchmark_results[timed_out]=FALSE))),"n/a")} -> 0.00065279999 | C7: {=IFERROR(MEDIAN(_xlfn._xlws.FILTER(benchmark_results[runtime_s],(benchmark_results[algo]=C$4)*(benchmark_results[n_tracks]=$A7)*(benchmark_results[timed_out]=FALSE))),"n/a")} -> 0.2152349 | D7: {=IFERROR(MEDIAN(_xlfn._xlws.FILTER(benchmark_results[runtime_s],(benchmark_results[algo]=D$4)*(benchmark_results[n_tracks]=$A7)*(benchmark_results[timed_out]=FALSE))),"n/a")} -> 0.0137826 | E7: {=IFERROR(MEDIAN(_xlfn._xlws.FILTER(benchmark_results[runtime_s],(benchmark_results[algo]=E$4)*(benchmark_results[n_tracks]=$A7)*(benchmark_results[timed_out]=FALSE))),"n/a")} -> 0.0051501 | F7: =$A7 -> 50 | G7: =IF(COUNTIFS(benchmark_results[algo],G$4,benchmark_results[n_tracks],$A7,benchmark_results[timed_out],FALSE)=0,"n/a",_xlfn.MAXIFS(benchmark_results[runtime_s],benchmark_results[algo],G$4,benchmark_results[n_tracks],$A7)) -> 0.0014076 | H7: =IF(COUNTIFS(benchmark_results[algo],H$4,benchmark_results[n_tracks],$A7,benchmark_results[timed_out],FALSE)=0,"n/a",_xlfn.MAXIFS(benchmark_results[runtime_s],benchmark_results[algo],H$4,benchmark_results[n_tracks],$A7)) -> 2.0185901 | I7: =IF(COUNTIFS(benchmark_results[algo],I$4,benchmark_results[n_tracks],$A7,benchmark_results[timed_out],FALSE)=0,"n/a",_xlfn.MAXIFS(benchmark_results[runtime_s],benchmark_results[algo],I$4,benchmark_results[n_tracks],$A7)) -> 0.1771605 | J7: =IF(COUNTIFS(benchmark_results[algo],J$4,benchmark_results[n_tracks],$A7,benchmark_results[timed_out],FALSE)=0,"n/a",_xlfn.MAXIFS(benchmark_results[runtime_s],benchmark_results[algo],J$4,benchmark_results[n_tracks],$A7)) -> 0.0733838 | K7: =$A7 -> 50 | L7: =COUNTIFS(benchmark_results[algo],L$4,benchmark_results[n_tracks],$A7,benchmark_results[timed_out],TRUE) -> 6 | M7: =COUNTIFS(benchmark_results[algo],M$4,benchmark_results[n_tracks],$A7,benchmark_results[timed_out],TRUE) -> 15 | N7: =COUNTIFS(benchmark_results[algo],N$4,benchmark_results[n_tracks],$A7,benchmark_results[timed_out],TRUE) -> 0 | O7: =COUNTIFS(benchmark_results[algo],O$4,benchmark_results[n_tracks],$A7,benchmark_results[timed_out],TRUE) -> 0 | P7: =$A7 -> 50 | Q7: =IFERROR(AVERAGEIFS(benchmark_results[gap_s],benchmark_results[algo],Q$4,benchmark_results[n_tracks],$A7,benchmark_results[timed_out],FALSE),"n/a") -> 0 | R7: =IFERROR(AVERAGEIFS(benchmark_results[gap_s],benchmark_results[algo],R$4,benchmark_results[n_tracks],$A7,benchmark_results[timed_out],FALSE),"n/a") -> 0 | S7: =IFERROR(AVERAGEIFS(benchmark_results[gap_s],benchmark_results[algo],S$4,benchmark_results[n_tracks],$A7,benchmark_results[timed_out],FALSE),"n/a") -> 0 | T7: =IFERROR(AVERAGEIFS(benchmark_results[gap_s],benchmark_results[algo],T$4,benchmark_results[n_tracks],$A7,benchmark_results[timed_out],FALSE),"n/a") -> 0 | V7: =TEXT($A7,"0") -> 50 | W7: {=IFERROR(MEDIAN(_xlfn._xlws.FILTER(benchmark_results[runtime_s],(benchmark_results[algo]="design_playlist_"&W$4)*(benchmark_results[n_tracks]=$A7)*(benchmark_results[timed_out]=FALSE))),NA())} -> 0.00065279999 | X7: {=IFERROR(MEDIAN(_xlfn._xlws.FILTER(benchmark_results[runtime_s],(benchmark_results[algo]="design_playlist_"&X$4)*(benchmark_results[n_tracks]=$A7)*(benchmark_results[timed_out]=FALSE))),NA())} -> 0.2152349 | Y7: {=IFERROR(MEDIAN(_xlfn._xlws.FILTER(benchmark_results[runtime_s],(benchmark_results[algo]="design_playlist_"&Y$4)*(benchmark_results[n_tracks]=$A7)*(benchmark_results[timed_out]=FALSE))),NA())} -> 0.0137826 | Z7: {=IFERROR(MEDIAN(_xlfn._xlws.FILTER(benchmark_results[runtime_s],(benchmark_results[algo]="design_playlist_"&Z$4)*(benchmark_results[n_tracks]=$A7)*(benchmark_results[timed_out]=FALSE))),NA())} -> 0.0051501 | AB7: =TEXT($A7,"0") -> 50 | AC7: =COUNTIFS(benchmark_results[algo],"design_playlist_"&AC$4,benchmark_results[n_tracks],$A7,benchmark_results[timed_out],TRUE) -> 6 | AD7: =COUNTIFS(benchmark_results[algo],"design_playlist_"&AD$4,benchmark_results[n_tracks],$A7,benchmark_results[timed_out],TRUE) -> 15 | AE7: =COUNTIFS(benchmark_results[algo],"design_playlist_"&AE$4,benchmark_results[n_tracks],$A7,benchmark_results[timed_out],TRUE) -> 0 | AF7: =COUNTIFS(benchmark_results[algo],"design_playlist_"&AF$4,benchmark_results[n_tracks],$A7,benchmark_results[timed_out],TRUE) -> 0
A8: 100 | B8: {=IFERROR(MEDIAN(_xlfn._xlws.FILTER(benchmark_results[runtime_s],(benchmark_results[algo]=B$4)*(benchmark_results[n_tracks]=$A8)*(benchmark_results[timed_out]=FALSE))),"n/a")} -> 0.00070734999 | C8: {=IFERROR(MEDIAN(_xlfn._xlws.FILTER(benchmark_results[runtime_s],(benchmark_results[algo]=C$4)*(benchmark_results[n_tracks]=$A8)*(benchmark_results[timed_out]=FALSE))),"n/a")} -> 0.3581277 | D8: {=IFERROR(MEDIAN(_xlfn._xlws.FILTER(benchmark_results[runtime_s],(benchmark_results[algo]=D$4)*(benchmark_results[n_tracks]=$A8)*(benchmark_results[timed_out]=FALSE))),"n/a")} -> 0.0412011 | E8: {=IFERROR(MEDIAN(_xlfn._xlws.FILTER(benchmark_results[runtime_s],(benchmark_results[algo]=E$4)*(benchmark_results[n_tracks]=$A8)*(benchmark_results[timed_out]=FALSE))),"n/a")} -> 0.014605 | F8: =$A8 -> 100 | G8: =IF(COUNTIFS(benchmark_results[algo],G$4,benchmark_results[n_tracks],$A8,benchmark_results[timed_out],FALSE)=0,"n/a",_xlfn.MAXIFS(benchmark_results[runtime_s],benchmark_results[algo],G$4,benchmark_results[n_tracks],$A8)) -> 0.010679 | H8: =IF(COUNTIFS(benchmark_results[algo],H$4,benchmark_results[n_tracks],$A8,benchmark_results[timed_out],FALSE)=0,"n/a",_xlfn.MAXIFS(benchmark_results[runtime_s],benchmark_results[algo],H$4,benchmark_results[n_tracks],$A8)) -> 0.4344965 | I8: =IF(COUNTIFS(benchmark_results[algo],I$4,benchmark_results[n_tracks],$A8,benchmark_results[timed_out],FALSE)=0,"n/a",_xlfn.MAXIFS(benchmark_results[runtime_s],benchmark_results[algo],I$4,benchmark_results[n_tracks],$A8)) -> 0.6273588 | J8: =IF(COUNTIFS(benchmark_results[algo],J$4,benchmark_results[n_tracks],$A8,benchmark_results[timed_out],FALSE)=0,"n/a",_xlfn.MAXIFS(benchmark_results[runtime_s],benchmark_results[algo],J$4,benchmark_results[n_tracks],$A8)) -> 0.2164121 | K8: =$A8 -> 100 | L8: =COUNTIFS(benchmark_results[algo],L$4,benchmark_results[n_tracks],$A8,benchmark_results[timed_out],TRUE) -> 3 | M8: =COUNTIFS(benchmark_results[algo],M$4,benchmark_results[n_tracks],$A8,benchmark_results[timed_out],TRUE) -> 20 | N8: =COUNTIFS(benchmark_results[algo],N$4,benchmark_results[n_tracks],$A8,benchmark_results[timed_out],TRUE) -> 0 | O8: =COUNTIFS(benchmark_results[algo],O$4,benchmark_results[n_tracks],$A8,benchmark_results[timed_out],TRUE) -> 0 | P8: =$A8 -> 100 | Q8: =IFERROR(AVERAGEIFS(benchmark_results[gap_s],benchmark_results[algo],Q$4,benchmark_results[n_tracks],$A8,benchmark_results[timed_out],FALSE),"n/a") -> 0 | R8: =IFERROR(AVERAGEIFS(benchmark_results[gap_s],benchmark_results[algo],R$4,benchmark_results[n_tracks],$A8,benchmark_results[timed_out],FALSE),"n/a") -> 0 | S8: =IFERROR(AVERAGEIFS(benchmark_results[gap_s],benchmark_results[algo],S$4,benchmark_results[n_tracks],$A8,benchmark_results[timed_out],FALSE),"n/a") -> 0 | T8: =IFERROR(AVERAGEIFS(benchmark_results[gap_s],benchmark_results[algo],T$4,benchmark_results[n_tracks],$A8,benchmark_results[timed_out],FALSE),"n/a") -> 0 | V8: =TEXT($A8,"0") -> 100 | W8: {=IFERROR(MEDIAN(_xlfn._xlws.FILTER(benchmark_results[runtime_s],(benchmark_results[algo]="design_playlist_"&W$4)*(benchmark_results[n_tracks]=$A8)*(benchmark_results[timed_out]=FALSE))),NA())} -> 0.00070734999 | X8: {=IFERROR(MEDIAN(_xlfn._xlws.FILTER(benchmark_results[runtime_s],(benchmark_results[algo]="design_playlist_"&X$4)*(benchmark_results[n_tracks]=$A8)*(benchmark_results[timed_out]=FALSE))),NA())} -> 0.3581277 | Y8: {=IFERROR(MEDIAN(_xlfn._xlws.FILTER(benchmark_results[runtime_s],(benchmark_results[algo]="design_playlist_"&Y$4)*(benchmark_results[n_tracks]=$A8)*(benchmark_results[timed_out]=FALSE))),NA())} -> 0.0412011 | Z8: {=IFERROR(MEDIAN(_xlfn._xlws.FILTER(benchmark_results[runtime_s],(benchmark_results[algo]="design_playlist_"&Z$4)*(benchmark_results[n_tracks]=$A8)*(benchmark_results[timed_out]=FALSE))),NA())} -> 0.014605 | AB8: =TEXT($A8,"0") -> 100 | AC8: =COUNTIFS(benchmark_results[algo],"design_playlist_"&AC$4,benchmark_results[n_tracks],$A8,benchmark_results[timed_out],TRUE) -> 3 | AD8: =COUNTIFS(benchmark_results[algo],"design_playlist_"&AD$4,benchmark_results[n_tracks],$A8,benchmark_results[timed_out],TRUE) -> 20 | AE8: =COUNTIFS(benchmark_results[algo],"design_playlist_"&AE$4,benchmark_results[n_tracks],$A8,benchmark_results[timed_out],TRUE) -> 0 | AF8: =COUNTIFS(benchmark_results[algo],"design_playlist_"&AF$4,benchmark_results[n_tracks],$A8,benchmark_results[timed_out],TRUE) -> 0
A9: 200 | B9: {=IFERROR(MEDIAN(_xlfn._xlws.FILTER(benchmark_results[runtime_s],(benchmark_results[algo]=B$4)*(benchmark_results[n_tracks]=$A9)*(benchmark_results[timed_out]=FALSE))),"n/a")} -> 0.000548 | C9: {=IFERROR(MEDIAN(_xlfn._xlws.FILTER(benchmark_results[runtime_s],(benchmark_results[algo]=C$4)*(benchmark_results[n_tracks]=$A9)*(benchmark_results[timed_out]=FALSE))),"n/a")} -> n/a | D9: {=IFERROR(MEDIAN(_xlfn._xlws.FILTER(benchmark_results[runtime_s],(benchmark_results[algo]=D$4)*(benchmark_results[n_tracks]=$A9)*(benchmark_results[timed_out]=FALSE))),"n/a")} -> 0.0886595 | E9: {=IFERROR(MEDIAN(_xlfn._xlws.FILTER(benchmark_results[runtime_s],(benchmark_results[algo]=E$4)*(benchmark_results[n_tracks]=$A9)*(benchmark_results[timed_out]=FALSE))),"n/a")} -> 0.0254293 | F9: =$A9 -> 200 | G9: =IF(COUNTIFS(benchmark_results[algo],G$4,benchmark_results[n_tracks],$A9,benchmark_results[timed_out],FALSE)=0,"n/a",_xlfn.MAXIFS(benchmark_results[runtime_s],benchmark_results[algo],G$4,benchmark_results[n_tracks],$A9)) -> 0.0047137 | H9: =IF(COUNTIFS(benchmark_results[algo],H$4,benchmark_results[n_tracks],$A9,benchmark_results[timed_out],FALSE)=0,"n/a",_xlfn.MAXIFS(benchmark_results[runtime_s],benchmark_results[algo],H$4,benchmark_results[n_tracks],$A9)) -> n/a | I9: =IF(COUNTIFS(benchmark_results[algo],I$4,benchmark_results[n_tracks],$A9,benchmark_results[timed_out],FALSE)=0,"n/a",_xlfn.MAXIFS(benchmark_results[runtime_s],benchmark_results[algo],I$4,benchmark_results[n_tracks],$A9)) -> 1.3760342 | J9: =IF(COUNTIFS(benchmark_results[algo],J$4,benchmark_results[n_tracks],$A9,benchmark_results[timed_out],FALSE)=0,"n/a",_xlfn.MAXIFS(benchmark_results[runtime_s],benchmark_results[algo],J$4,benchmark_results[n_tracks],$A9)) -> 0.6788875 | K9: =$A9 -> 200 | L9: =COUNTIFS(benchmark_results[algo],L$4,benchmark_results[n_tracks],$A9,benchmark_results[timed_out],TRUE) -> 0 | M9: =COUNTIFS(benchmark_results[algo],M$4,benchmark_results[n_tracks],$A9,benchmark_results[timed_out],TRUE) -> 25 | N9: =COUNTIFS(benchmark_results[algo],N$4,benchmark_results[n_tracks],$A9,benchmark_results[timed_out],TRUE) -> 0 | O9: =COUNTIFS(benchmark_results[algo],O$4,benchmark_results[n_tracks],$A9,benchmark_results[timed_out],TRUE) -> 0 | P9: =$A9 -> 200 | Q9: =IFERROR(AVERAGEIFS(benchmark_results[gap_s],benchmark_results[algo],Q$4,benchmark_results[n_tracks],$A9,benchmark_results[timed_out],FALSE),"n/a") -> 0 | R9: =IFERROR(AVERAGEIFS(benchmark_results[gap_s],benchmark_results[algo],R$4,benchmark_results[n_tracks],$A9,benchmark_results[timed_out],FALSE),"n/a") -> n/a | S9: =IFERROR(AVERAGEIFS(benchmark_results[gap_s],benchmark_results[algo],S$4,benchmark_results[n_tracks],$A9,benchmark_results[timed_out],FALSE),"n/a") -> 0 | T9: =IFERROR(AVERAGEIFS(benchmark_results[gap_s],benchmark_results[algo],T$4,benchmark_results[n_tracks],$A9,benchmark_results[timed_out],FALSE),"n/a") -> 0 | V9: =TEXT($A9,"0") -> 200 | W9: {=IFERROR(MEDIAN(_xlfn._xlws.FILTER(benchmark_results[runtime_s],(benchmark_results[algo]="design_playlist_"&W$4)*(benchmark_results[n_tracks]=$A9)*(benchmark_results[timed_out]=FALSE))),NA())} -> 0.000548 | X9: {=IFERROR(MEDIAN(_xlfn._xlws.FILTER(benchmark_results[runtime_s],(benchmark_results[algo]="design_playlist_"&X$4)*(benchmark_results[n_tracks]=$A9)*(benchmark_results[timed_out]=FALSE))),NA())} -> #N/A | Y9: {=IFERROR(MEDIAN(_xlfn._xlws.FILTER(benchmark_results[runtime_s],(benchmark_results[algo]="design_playlist_"&Y$4)*(benchmark_results[n_tracks]=$A9)*(benchmark_results[timed_out]=FALSE))),NA())} -> 0.0886595 | Z9: {=IFERROR(MEDIAN(_xlfn._xlws.FILTER(benchmark_results[runtime_s],(benchmark_results[algo]="design_playlist_"&Z$4)*(benchmark_results[n_tracks]=$A9)*(benchmark_results[timed_out]=FALSE))),NA())} -> 0.0254293 | AB9: =TEXT($A9,"0") -> 200 | AC9: =COUNTIFS(benchmark_results[algo],"design_playlist_"&AC$4,benchmark_results[n_tracks],$A9,benchmark_results[timed_out],TRUE) -> 0 | AD9: =COUNTIFS(benchmark_results[algo],"design_playlist_"&AD$4,benchmark_results[n_tracks],$A9,benchmark_results[timed_out],TRUE) -> 25 | AE9: =COUNTIFS(benchmark_results[algo],"design_playlist_"&AE$4,benchmark_results[n_tracks],$A9,benchmark_results[timed_out],TRUE) -> 0 | AF9: =COUNTIFS(benchmark_results[algo],"design_playlist_"&AF$4,benchmark_results[n_tracks],$A9,benchmark_results[timed_out],TRUE) -> 0
A10: 400 | B10: {=IFERROR(MEDIAN(_xlfn._xlws.FILTER(benchmark_results[runtime_s],(benchmark_results[algo]=B$4)*(benchmark_results[n_tracks]=$A10)*(benchmark_results[timed_out]=FALSE))),"n/a")} -> 0.000655 | C10: {=IFERROR(MEDIAN(_xlfn._xlws.FILTER(benchmark_results[runtime_s],(benchmark_results[algo]=C$4)*(benchmark_results[n_tracks]=$A10)*(benchmark_results[timed_out]=FALSE))),"n/a")} -> n/a | D10: {=IFERROR(MEDIAN(_xlfn._xlws.FILTER(benchmark_results[runtime_s],(benchmark_results[algo]=D$4)*(benchmark_results[n_tracks]=$A10)*(benchmark_results[timed_out]=FALSE))),"n/a")} -> 0.1920098 | E10: {=IFERROR(MEDIAN(_xlfn._xlws.FILTER(benchmark_results[runtime_s],(benchmark_results[algo]=E$4)*(benchmark_results[n_tracks]=$A10)*(benchmark_results[timed_out]=FALSE))),"n/a")} -> 0.0674693 | F10: =$A10 -> 400 | G10: =IF(COUNTIFS(benchmark_results[algo],G$4,benchmark_results[n_tracks],$A10,benchmark_results[timed_out],FALSE)=0,"n/a",_xlfn.MAXIFS(benchmark_results[runtime_s],benchmark_results[algo],G$4,benchmark_results[n_tracks],$A10)) -> 0.0113342 | H10: =IF(COUNTIFS(benchmark_results[algo],H$4,benchmark_results[n_tracks],$A10,benchmark_results[timed_out],FALSE)=0,"n/a",_xlfn.MAXIFS(benchmark_results[runtime_s],benchmark_results[algo],H$4,benchmark_results[n_tracks],$A10)) -> n/a | I10: =IF(COUNTIFS(benchmark_results[algo],I$4,benchmark_results[n_tracks],$A10,benchmark_results[timed_out],FALSE)=0,"n/a",_xlfn.MAXIFS(benchmark_results[runtime_s],benchmark_results[algo],I$4,benchmark_results[n_tracks],$A10)) -> 4.1035292 | J10: =IF(COUNTIFS(benchmark_results[algo],J$4,benchmark_results[n_tracks],$A10,benchmark_results[timed_out],FALSE)=0,"n/a",_xlfn.MAXIFS(benchmark_results[runtime_s],benchmark_results[algo],J$4,benchmark_results[n_tracks],$A10)) -> 1.490365 | K10: =$A10 -> 400 | L10: =COUNTIFS(benchmark_results[algo],L$4,benchmark_results[n_tracks],$A10,benchmark_results[timed_out],TRUE) -> 3 | M10: =COUNTIFS(benchmark_results[algo],M$4,benchmark_results[n_tracks],$A10,benchmark_results[timed_out],TRUE) -> 25 | N10: =COUNTIFS(benchmark_results[algo],N$4,benchmark_results[n_tracks],$A10,benchmark_results[timed_out],TRUE) -> 0 | O10: =COUNTIFS(benchmark_results[algo],O$4,benchmark_results[n_tracks],$A10,benchmark_results[timed_out],TRUE) -> 0 | P10: =$A10 -> 400 | Q10: =IFERROR(AVERAGEIFS(benchmark_results[gap_s],benchmark_results[algo],Q$4,benchmark_results[n_tracks],$A10,benchmark_results[timed_out],FALSE),"n/a") -> 0 | R10: =IFERROR(AVERAGEIFS(benchmark_results[gap_s],benchmark_results[algo],R$4,benchmark_results[n_tracks],$A10,benchmark_results[timed_out],FALSE),"n/a") -> n/a | S10: =IFERROR(AVERAGEIFS(benchmark_results[gap_s],benchmark_results[algo],S$4,benchmark_results[n_tracks],$A10,benchmark_results[timed_out],FALSE),"n/a") -> 0 | T10: =IFERROR(AVERAGEIFS(benchmark_results[gap_s],benchmark_results[algo],T$4,benchmark_results[n_tracks],$A10,benchmark_results[timed_out],FALSE),"n/a") -> 0 | V10: =TEXT($A10,"0") -> 400 | W10: {=IFERROR(MEDIAN(_xlfn._xlws.FILTER(benchmark_results[runtime_s],(benchmark_results[algo]="design_playlist_"&W$4)*(benchmark_results[n_tracks]=$A10)*(benchmark_results[timed_out]=FALSE))),NA())} -> 0.000655 | X10: {=IFERROR(MEDIAN(_xlfn._xlws.FILTER(benchmark_results[runtime_s],(benchmark_results[algo]="design_playlist_"&X$4)*(benchmark_results[n_tracks]=$A10)*(benchmark_results[timed_out]=FALSE))),NA())} -> #N/A | Y10: {=IFERROR(MEDIAN(_xlfn._xlws.FILTER(benchmark_results[runtime_s],(benchmark_results[algo]="design_playlist_"&Y$4)*(benchmark_results[n_tracks]=$A10)*(benchmark_results[timed_out]=FALSE))),NA())} -> 0.1920098 | Z10: {=IFERROR(MEDIAN(_xlfn._xlws.FILTER(benchmark_results[runtime_s],(benchmark_results[algo]="design_playlist_"&Z$4)*(benchmark_results[n_tracks]=$A10)*(benchmark_results[timed_out]=FALSE))),NA())} -> 0.0674693 | AB10: =TEXT($A10,"0") -> 400 | AC10: =COUNTIFS(benchmark_results[algo],"design_playlist_"&AC$4,benchmark_results[n_tracks],$A10,benchmark_results[timed_out],TRUE) -> 3 | AD10: =COUNTIFS(benchmark_results[algo],"design_playlist_"&AD$4,benchmark_results[n_tracks],$A10,benchmark_results[timed_out],TRUE) -> 25 | AE10: =COUNTIFS(benchmark_results[algo],"design_playlist_"&AE$4,benchmark_results[n_tracks],$A10,benchmark_results[timed_out],TRUE) -> 0 | AF10: =COUNTIFS(benchmark_results[algo],"design_playlist_"&AF$4,benchmark_results[n_tracks],$A10,benchmark_results[timed_out],TRUE) -> 0
A12: Scaling behaviour — fit of median runtime against playlist size (log-log)
A13: Scaling exponent (slope) | B13: {=IFERROR(SLOPE(LOG10(B$5:B$10),LOG10($A$5:$A$10)),"n/a")} -> 0.82499853 | C13: {=IFERROR(SLOPE(LOG10(C$5:C$10),LOG10($A$5:$A$10)),"n/a")} -> n/a | D13: {=IFERROR(SLOPE(LOG10(D$5:D$10),LOG10($A$5:$A$10)),"n/a")} -> 1.6233052 | E13: {=IFERROR(SLOPE(LOG10(E$5:E$10),LOG10($A$5:$A$10)),"n/a")} -> 1.4356697
A14: Runtime multiple per doubling of n | B14: =IFERROR(2^B13,"n/a") -> 1.7715332 | C14: =IFERROR(2^C13,"n/a") -> n/a | D14: =IFERROR(2^D13,"n/a") -> 3.0808003 | E14: =IFERROR(2^E13,"n/a") -> 2.705077
A15: R² of log-log fit | B15: {=IFERROR(RSQ(LOG10(B$5:B$10),LOG10($A$5:$A$10)),"n/a")} -> 0.64508479 | C15: {=IFERROR(RSQ(LOG10(C$5:C$10),LOG10($A$5:$A$10)),"n/a")} -> n/a | D15: {=IFERROR(RSQ(LOG10(D$5:D$10),LOG10($A$5:$A$10)),"n/a")} -> 0.94192279 | E15: {=IFERROR(RSQ(LOG10(E$5:E$10),LOG10($A$5:$A$10)),"n/a")} -> 0.96812822
A17: Note: at n_tracks = 10 the 3600 s and 7200 s targets are unreachable with any algorithm (too little material), so the large mean gaps in that row are instance infeasibility, not algorithm error.

Sheet By Target
A1: Runtime & reliability by duration target (target_s)
A2: Aggregated across 5 rounds x 6 playlist sizes = 30 runs per algorithm per target. Runtime statistics cover completed runs only.
B3: Median runtime (s), completed runs | G3: Max runtime (s), completed runs | L3: Timeouts (of 30 runs) | Q3: Mean gap (s), completed runs | V3: Chart source — median runtime (s); #N/A = never completed | AB3: Chart source — timeouts (of 30 runs)
A4: target_s | B4: design_playlist_v1 | C4: design_playlist_v2 | D4: design_playlist_v3 | E4: design_playlist_v4 | F4: target_s | G4: design_playlist_v1 | H4: design_playlist_v2 | I4: design_playlist_v3 | J4: design_playlist_v4 | K4: target_s | L4: design_playlist_v1 | M4: design_playlist_v2 | N4: design_playlist_v3 | O4: design_playlist_v4 | P4: target_s | Q4: design_playlist_v1 | R4: design_playlist_v2 | S4: design_playlist_v3 | T4: design_playlist_v4 | V4: target_s | W4: v1 | X4: v2 | Y4: v3 | Z4: v4 | AB4: target_s | AC4: v1 | AD4: v2 | AE4: v3 | AF4: v4
A5: 300 | B5: {=IFERROR(MEDIAN(_xlfn._xlws.FILTER(benchmark_results[runtime_s],(benchmark_results[algo]=B$4)*(benchmark_results[target_s]=$A5)*(benchmark_results[timed_out]=FALSE))),"n/a")} -> 0.00037235 | C5: {=IFERROR(MEDIAN(_xlfn._xlws.FILTER(benchmark_results[runtime_s],(benchmark_results[algo]=C$4)*(benchmark_results[target_s]=$A5)*(benchmark_results[timed_out]=FALSE))),"n/a")} -> 0.00444035 | D5: {=IFERROR(MEDIAN(_xlfn._xlws.FILTER(benchmark_results[runtime_s],(benchmark_results[algo]=D$4)*(benchmark_results[target_s]=$A5)*(benchmark_results[timed_out]=FALSE))),"n/a")} -> 0.0015708 | E5: {=IFERROR(MEDIAN(_xlfn._xlws.FILTER(benchmark_results[runtime_s],(benchmark_results[algo]=E$4)*(benchmark_results[target_s]=$A5)*(benchmark_results[timed_out]=FALSE))),"n/a")} -> 0.00096885001 | F5: =$A5 -> 300 | G5: =IF(COUNTIFS(benchmark_results[algo],G$4,benchmark_results[target_s],$A5,benchmark_results[timed_out],FALSE)=0,"n/a",_xlfn.MAXIFS(benchmark_results[runtime_s],benchmark_results[algo],G$4,benchmark_results[target_s],$A5)) -> 0.0021921 | H5: =IF(COUNTIFS(benchmark_results[algo],H$4,benchmark_results[target_s],$A5,benchmark_results[timed_out],FALSE)=0,"n/a",_xlfn.MAXIFS(benchmark_results[runtime_s],benchmark_results[algo],H$4,benchmark_results[target_s],$A5)) -> 0.4344965 | I5: =IF(COUNTIFS(benchmark_results[algo],I$4,benchmark_results[target_s],$A5,benchmark_results[timed_out],FALSE)=0,"n/a",_xlfn.MAXIFS(benchmark_results[runtime_s],benchmark_results[algo],I$4,benchmark_results[target_s],$A5)) -> 0.0213538 | J5: =IF(COUNTIFS(benchmark_results[algo],J$4,benchmark_results[target_s],$A5,benchmark_results[timed_out],FALSE)=0,"n/a",_xlfn.MAXIFS(benchmark_results[runtime_s],benchmark_results[algo],J$4,benchmark_results[target_s],$A5)) -> 0.0121063 | K5: =$A5 -> 300 | L5: =COUNTIFS(benchmark_results[algo],L$4,benchmark_results[target_s],$A5,benchmark_results[timed_out],TRUE) -> 20 | M5: =COUNTIFS(benchmark_results[algo],M$4,benchmark_results[target_s],$A5,benchmark_results[timed_out],TRUE) -> 10 | N5: =COUNTIFS(benchmark_results[algo],N$4,benchmark_results[target_s],$A5,benchmark_results[timed_out],TRUE) -> 0 | O5: =COUNTIFS(benchmark_results[algo],O$4,benchmark_results[target_s],$A5,benchmark_results[timed_out],TRUE) -> 0 | P5: =$A5 -> 300 | Q5: =IFERROR(AVERAGEIFS(benchmark_results[gap_s],benchmark_results[algo],Q$4,benchmark_results[target_s],$A5,benchmark_results[timed_out],FALSE),"n/a") -> 0 | R5: =IFERROR(AVERAGEIFS(benchmark_results[gap_s],benchmark_results[algo],R$4,benchmark_results[target_s],$A5,benchmark_results[timed_out],FALSE),"n/a") -> 1.15 | S5: =IFERROR(AVERAGEIFS(benchmark_results[gap_s],benchmark_results[algo],S$4,benchmark_results[target_s],$A5,benchmark_results[timed_out],FALSE),"n/a") -> 0.76666667 | T5: =IFERROR(AVERAGEIFS(benchmark_results[gap_s],benchmark_results[algo],T$4,benchmark_results[target_s],$A5,benchmark_results[timed_out],FALSE),"n/a") -> 0.76666667 | V5: =TEXT($A5,"0") -> 300 | W5: {=IFERROR(MEDIAN(_xlfn._xlws.FILTER(benchmark_results[runtime_s],(benchmark_results[algo]="design_playlist_"&W$4)*(benchmark_results[target_s]=$A5)*(benchmark_results[timed_out]=FALSE))),NA())} -> 0.00037235 | X5: {=IFERROR(MEDIAN(_xlfn._xlws.FILTER(benchmark_results[runtime_s],(benchmark_results[algo]="design_playlist_"&X$4)*(benchmark_results[target_s]=$A5)*(benchmark_results[timed_out]=FALSE))),NA())} -> 0.00444035 | Y5: {=IFERROR(MEDIAN(_xlfn._xlws.FILTER(benchmark_results[runtime_s],(benchmark_results[algo]="design_playlist_"&Y$4)*(benchmark_results[target_s]=$A5)*(benchmark_results[timed_out]=FALSE))),NA())} -> 0.0015708 | Z5: {=IFERROR(MEDIAN(_xlfn._xlws.FILTER(benchmark_results[runtime_s],(benchmark_results[algo]="design_playlist_"&Z$4)*(benchmark_results[target_s]=$A5)*(benchmark_results[timed_out]=FALSE))),NA())} -> 0.00096885001 | AB5: =TEXT($A5,"0") -> 300 | AC5: =COUNTIFS(benchmark_results[algo],"design_playlist_"&AC$4,benchmark_results[target_s],$A5,benchmark_results[timed_out],TRUE) -> 20 | AD5: =COUNTIFS(benchmark_results[algo],"design_playlist_"&AD$4,benchmark_results[target_s],$A5,benchmark_results[timed_out],TRUE) -> 10 | AE5: =COUNTIFS(benchmark_results[algo],"design_playlist_"&AE$4,benchmark_results[target_s],$A5,benchmark_results[timed_out],TRUE) -> 0 | AF5: =COUNTIFS(benchmark_results[algo],"design_playlist_"&AF$4,benchmark_results[target_s],$A5,benchmark_results[timed_out],TRUE) -> 0
A6: 600 | B6: {=IFERROR(MEDIAN(_xlfn._xlws.FILTER(benchmark_results[runtime_s],(benchmark_results[algo]=B$4)*(benchmark_results[target_s]=$A6)*(benchmark_results[timed_out]=FALSE))),"n/a")} -> 0.0013999 | C6: {=IFERROR(MEDIAN(_xlfn._xlws.FILTER(benchmark_results[runtime_s],(benchmark_results[algo]=C$4)*(benchmark_results[target_s]=$A6)*(benchmark_results[timed_out]=FALSE))),"n/a")} -> 0.0280758 | D6: {=IFERROR(MEDIAN(_xlfn._xlws.FILTER(benchmark_results[runtime_s],(benchmark_results[algo]=D$4)*(benchmark_results[target_s]=$A6)*(benchmark_results[timed_out]=FALSE))),"n/a")} -> 0.0077806 | E6: {=IFERROR(MEDIAN(_xlfn._xlws.FILTER(benchmark_results[runtime_s],(benchmark_results[algo]=E$4)*(benchmark_results[target_s]=$A6)*(benchmark_results[timed_out]=FALSE))),"n/a")} -> 0.0035948 | F6: =$A6 -> 600 | G6: =IF(COUNTIFS(benchmark_results[algo],G$4,benchmark_results[target_s],$A6,benchmark_results[timed_out],FALSE)=0,"n/a",_xlfn.MAXIFS(benchmark_results[runtime_s],benchmark_results[algo],G$4,benchmark_results[target_s],$A6)) -> 0.0113342 | H6: =IF(COUNTIFS(benchmark_results[algo],H$4,benchmark_results[target_s],$A6,benchmark_results[timed_out],FALSE)=0,"n/a",_xlfn.MAXIFS(benchmark_results[runtime_s],benchmark_results[algo],H$4,benchmark_results[target_s],$A6)) -> 2.0185901 | I6: =IF(COUNTIFS(benchmark_results[algo],I$4,benchmark_results[target_s],$A6,benchmark_results[timed_out],FALSE)=0,"n/a",_xlfn.MAXIFS(benchmark_results[runtime_s],benchmark_results[algo],I$4,benchmark_results[target_s],$A6)) -> 0.1766287 | J6: =IF(COUNTIFS(benchmark_results[algo],J$4,benchmark_results[target_s],$A6,benchmark_results[timed_out],FALSE)=0,"n/a",_xlfn.MAXIFS(benchmark_results[runtime_s],benchmark_results[algo],J$4,benchmark_results[target_s],$A6)) -> 0.0791766 | K6: =$A6 -> 600 | L6: =COUNTIFS(benchmark_results[algo],L$4,benchmark_results[target_s],$A6,benchmark_results[timed_out],TRUE) -> 11 | M6: =COUNTIFS(benchmark_results[algo],M$4,benchmark_results[target_s],$A6,benchmark_results[timed_out],TRUE) -> 15 | N6: =COUNTIFS(benchmark_results[algo],N$4,benchmark_results[target_s],$A6,benchmark_results[timed_out],TRUE) -> 0 | O6: =COUNTIFS(benchmark_results[algo],O$4,benchmark_results[target_s],$A6,benchmark_results[timed_out],TRUE) -> 0 | P6: =$A6 -> 600 | Q6: =IFERROR(AVERAGEIFS(benchmark_results[gap_s],benchmark_results[algo],Q$4,benchmark_results[target_s],$A6,benchmark_results[timed_out],FALSE),"n/a") -> 0 | R6: =IFERROR(AVERAGEIFS(benchmark_results[gap_s],benchmark_results[algo],R$4,benchmark_results[target_s],$A6,benchmark_results[timed_out],FALSE),"n/a") -> 0.86666667 | S6: =IFERROR(AVERAGEIFS(benchmark_results[gap_s],benchmark_results[algo],S$4,benchmark_results[target_s],$A6,benchmark_results[timed_out],FALSE),"n/a") -> 0.4 | T6: =IFERROR(AVERAGEIFS(benchmark_results[gap_s],benchmark_results[algo],T$4,benchmark_results[target_s],$A6,benchmark_results[timed_out],FALSE),"n/a") -> 0.4 | V6: =TEXT($A6,"0") -> 600 | W6: {=IFERROR(MEDIAN(_xlfn._xlws.FILTER(benchmark_results[runtime_s],(benchmark_results[algo]="design_playlist_"&W$4)*(benchmark_results[target_s]=$A6)*(benchmark_results[timed_out]=FALSE))),NA())} -> 0.0013999 | X6: {=IFERROR(MEDIAN(_xlfn._xlws.FILTER(benchmark_results[runtime_s],(benchmark_results[algo]="design_playlist_"&X$4)*(benchmark_results[target_s]=$A6)*(benchmark_results[timed_out]=FALSE))),NA())} -> 0.0280758 | Y6: {=IFERROR(MEDIAN(_xlfn._xlws.FILTER(benchmark_results[runtime_s],(benchmark_results[algo]="design_playlist_"&Y$4)*(benchmark_results[target_s]=$A6)*(benchmark_results[timed_out]=FALSE))),NA())} -> 0.0077806 | Z6: {=IFERROR(MEDIAN(_xlfn._xlws.FILTER(benchmark_results[runtime_s],(benchmark_results[algo]="design_playlist_"&Z$4)*(benchmark_results[target_s]=$A6)*(benchmark_results[timed_out]=FALSE))),NA())} -> 0.0035948 | AB6: =TEXT($A6,"0") -> 600 | AC6: =COUNTIFS(benchmark_results[algo],"design_playlist_"&AC$4,benchmark_results[target_s],$A6,benchmark_results[timed_out],TRUE) -> 11 | AD6: =COUNTIFS(benchmark_results[algo],"design_playlist_"&AD$4,benchmark_results[target_s],$A6,benchmark_results[timed_out],TRUE) -> 15 | AE6: =COUNTIFS(benchmark_results[algo],"design_playlist_"&AE$4,benchmark_results[target_s],$A6,benchmark_results[timed_out],TRUE) -> 0 | AF6: =COUNTIFS(benchmark_results[algo],"design_playlist_"&AF$4,benchmark_results[target_s],$A6,benchmark_results[timed_out],TRUE) -> 0
A7: 1200 | B7: {=IFERROR(MEDIAN(_xlfn._xlws.FILTER(benchmark_results[runtime_s],(benchmark_results[algo]=B$4)*(benchmark_results[target_s]=$A7)*(benchmark_results[timed_out]=FALSE))),"n/a")} -> 0.0009 | C7: {=IFERROR(MEDIAN(_xlfn._xlws.FILTER(benchmark_results[runtime_s],(benchmark_results[algo]=C$4)*(benchmark_results[target_s]=$A7)*(benchmark_results[timed_out]=FALSE))),"n/a")} -> 0.43352765 | D7: {=IFERROR(MEDIAN(_xlfn._xlws.FILTER(benchmark_results[runtime_s],(benchmark_results[algo]=D$4)*(benchmark_results[target_s]=$A7)*(benchmark_results[timed_out]=FALSE))),"n/a")} -> 0.03285785 | E7: {=IFERROR(MEDIAN(_xlfn._xlws.FILTER(benchmark_results[runtime_s],(benchmark_results[algo]=E$4)*(benchmark_results[target_s]=$A7)*(benchmark_results[timed_out]=FALSE))),"n/a")} -> 0.00944495 | F7: =$A7 -> 1200 | G7: =IF(COUNTIFS(benchmark_results[algo],G$4,benchmark_results[target_s],$A7,benchmark_results[timed_out],FALSE)=0,"n/a",_xlfn.MAXIFS(benchmark_results[runtime_s],benchmark_results[algo],G$4,benchmark_results[target_s],$A7)) -> 0.0042512 | H7: =IF(COUNTIFS(benchmark_results[algo],H$4,benchmark_results[target_s],$A7,benchmark_results[timed_out],FALSE)=0,"n/a",_xlfn.MAXIFS(benchmark_results[runtime_s],benchmark_results[algo],H$4,benchmark_results[target_s],$A7)) -> 7.0573739 | I7: =IF(COUNTIFS(benchmark_results[algo],I$4,benchmark_results[target_s],$A7,benchmark_results[timed_out],FALSE)=0,"n/a",_xlfn.MAXIFS(benchmark_results[runtime_s],benchmark_results[algo],I$4,benchmark_results[target_s],$A7)) -> 0.2339252 | J7: =IF(COUNTIFS(benchmark_results[algo],J$4,benchmark_results[target_s],$A7,benchmark_results[timed_out],FALSE)=0,"n/a",_xlfn.MAXIFS(benchmark_results[runtime_s],benchmark_results[algo],J$4,benchmark_results[target_s],$A7)) -> 0.0711167 | K7: =$A7 -> 1200 | L7: =COUNTIFS(benchmark_results[algo],L$4,benchmark_results[target_s],$A7,benchmark_results[timed_out],TRUE) -> 5 | M7: =COUNTIFS(benchmark_results[algo],M$4,benchmark_results[target_s],$A7,benchmark_results[timed_out],TRUE) -> 20 | N7: =COUNTIFS(benchmark_results[algo],N$4,benchmark_results[target_s],$A7,benchmark_results[timed_out],TRUE) -> 0 | O7: =COUNTIFS(benchmark_results[algo],O$4,benchmark_results[target_s],$A7,benchmark_results[timed_out],TRUE) -> 0 | P7: =$A7 -> 1200 | Q7: =IFERROR(AVERAGEIFS(benchmark_results[gap_s],benchmark_results[algo],Q$4,benchmark_results[target_s],$A7,benchmark_results[timed_out],FALSE),"n/a") -> 0 | R7: =IFERROR(AVERAGEIFS(benchmark_results[gap_s],benchmark_results[algo],R$4,benchmark_results[target_s],$A7,benchmark_results[timed_out],FALSE),"n/a") -> 0.2 | S7: =IFERROR(AVERAGEIFS(benchmark_results[gap_s],benchmark_results[algo],S$4,benchmark_results[target_s],$A7,benchmark_results[timed_out],FALSE),"n/a") -> 0.13333333 | T7: =IFERROR(AVERAGEIFS(benchmark_results[gap_s],benchmark_results[algo],T$4,benchmark_results[target_s],$A7,benchmark_results[timed_out],FALSE),"n/a") -> 0.1 | V7: =TEXT($A7,"0") -> 1200 | W7: {=IFERROR(MEDIAN(_xlfn._xlws.FILTER(benchmark_results[runtime_s],(benchmark_results[algo]="design_playlist_"&W$4)*(benchmark_results[target_s]=$A7)*(benchmark_results[timed_out]=FALSE))),NA())} -> 0.0009 | X7: {=IFERROR(MEDIAN(_xlfn._xlws.FILTER(benchmark_results[runtime_s],(benchmark_results[algo]="design_playlist_"&X$4)*(benchmark_results[target_s]=$A7)*(benchmark_results[timed_out]=FALSE))),NA())} -> 0.43352765 | Y7: {=IFERROR(MEDIAN(_xlfn._xlws.FILTER(benchmark_results[runtime_s],(benchmark_results[algo]="design_playlist_"&Y$4)*(benchmark_results[target_s]=$A7)*(benchmark_results[timed_out]=FALSE))),NA())} -> 0.03285785 | Z7: {=IFERROR(MEDIAN(_xlfn._xlws.FILTER(benchmark_results[runtime_s],(benchmark_results[algo]="design_playlist_"&Z$4)*(benchmark_results[target_s]=$A7)*(benchmark_results[timed_out]=FALSE))),NA())} -> 0.00944495 | AB7: =TEXT($A7,"0") -> 1200 | AC7: =COUNTIFS(benchmark_results[algo],"design_playlist_"&AC$4,benchmark_results[target_s],$A7,benchmark_results[timed_out],TRUE) -> 5 | AD7: =COUNTIFS(benchmark_results[algo],"design_playlist_"&AD$4,benchmark_results[target_s],$A7,benchmark_results[timed_out],TRUE) -> 20 | AE7: =COUNTIFS(benchmark_results[algo],"design_playlist_"&AE$4,benchmark_results[target_s],$A7,benchmark_results[timed_out],TRUE) -> 0 | AF7: =COUNTIFS(benchmark_results[algo],"design_playlist_"&AF$4,benchmark_results[target_s],$A7,benchmark_results[timed_out],TRUE) -> 0
